Workbook

Sheet MAESTRA
A1: ID | B1: Orden | C1: Categoria | D1: Nombre_CAT | E1: Descripcion_CAT | F1: Nombre_ES | G1: Descripcion_ES | H1: Nombre_FR | I1: Descripcion_FR | J1: Nombre_EN | K1: Descripcion_EN | L1: Precio_restaurante_EUR | M1: Increment_delivery_EUR | N1: Precio_delivery_EUR | O1: Restaurante | P1: Web | Q1: Delivery_TakeAway | R1: Imagen_URL
A2: BC-001 | B2: 1 | C2: entrants | D2: PA DE PIZZA | E2: Massa normal / integral | F2: Pan de pizza | G2: Masa normal / integral | H2: Pain à pizza | I2: Pâte classique / complète | J2: Pizza bread | K2: Regular / whole-wheat dough | L2: 5 | M2: 0 | N2: =L2+M2 -> 5 | O2: TRUE | P2: TRUE | Q2: TRUE
A3: BC-002 | B3: 2 | C3: entrants | D3: FOCACCIA | F3: FOCACCIA | H3: FOCACCIA | J3: FOCACCIA | L3: 5 | M3: 0 | N3: =L3+M3 -> 5 | O3: TRUE | P3: TRUE | Q3: TRUE
A4: BC-003 | B4: 3 | C4: entrants | D4: PROVOLONE | F4: PROVOLONE | H4: PROVOLONE | J4: PROVOLONE | L4: 10 | M4: 0 | N4: =L4+M4 -> 10 | O4: TRUE | P4: TRUE | Q4: TRUE
A5: BC-004 | B5: 4 | C5: entrants | D5: POLPETTINES D’ALBERGÍNIA | E5: 6 unitats (cada unitat addicional +1,75 €) | F5: Albóndigas de berenjena | G5: 6 unidades (unidad adicional +1,75 €) | H5: Boulettes d’aubergine | I5: 6 pièces (pièce supplémentaire +1,75 €) | J5: Aubergine balls | K5: 6 pieces (extra piece +€1.75) | L5: 9 | M5: 0 | N5: =L5+M5 -> 9 | O5: TRUE | P5: TRUE | Q5: FALSE
A6: BC-005 | B6: 5 | C6: entrants | D6: VITELLO TONNATO | E6: Utilitzem carn de vedell / amb salsa de tonyina | F6: VITELLO TONNATO | G6: Carne de ternera / salsa de atún | H6: VITELLO TONNATO | I6: Veau / sauce au thon | J6: VITELLO TONNATO | K6: Veal / tuna sauce | L6: 16.5 | M6: 0 | N6: =L6+M6 -> 16.5 | O6: TRUE | P6: TRUE | Q6: FALSE
A7: BC-006 | B7: 6 | C7: entrants | D7: BURRATA | E7: Amb salsa pesto o tòfona / tomàquet sec casolà / ruca / pa | F7: BURRATA | G7: Con pesto o salsa de trufa / tomate seco casero / rúcula / pan | H7: BURRATA | I7: Sauce pesto ou truffe / tomates séchées maison / roquette / pain | J7: BURRATA | K7: Pesto or truffle sauce / house-made sun-dried tomatoes / rocket / bread | L7: 15.5 | M7: 0 | N7: =L7+M7 -> 15.5 | O7: TRUE | P7: TRUE | Q7: FALSE
A8: BC-007 | B8: 7 | C8: entrants | D8: CARPACCIO DE CARBASSÓ | E8: Amb tomàquets secs, stracciatella i pinyons | F8: Carpaccio de calabacín | G8: Con tomates secos, stracciatella y piñones | H8: Carpaccio de courgette | I8: Avec tomates séchées, stracciatella et pignons | J8: Courgette carpaccio | K8: With sun-dried tomatoes, stracciatella and pine nuts | L8: 15.5 | M8: 0 | N8: =L8+M8 -> 15.5 | O8: TRUE | P8: TRUE | Q8: FALSE
A9: BC-008 | B9: 8 | C9: amanides | D9: BELLA CIAO | E9: Albergínia / tomàquet / filadèlfia / julivert / menta / salsa de xili dolça / sèsamo | F9: BELLA CIAO | G9: Berenjena / Tomate / Queso crema / Perejil / Menta / Salsa de chile dulce / Sésamo | H9: BELLA CIAO | I9: Aubergine / Tomate / Fromage frais / Persil / Menthe / Sauce chili douce / Sésame | J9: BELLA CIAO | K9: Aubergine / Tomato / Cream cheese / Parsley / Mint / Sweet chili sauce / Sesame | L9: 16 | M9: 0 | N9: =L9+M9 -> 16 | O9: TRUE | P9: TRUE | Q9: FALSE
A10: BC-009 | B10: 9 | C10: amanides | D10: BUFALATA | E10: Mesclum / burrata / bresaola / nous / olives | F10: BUFALATA | G10: Mezcla de hojas verdes / Burrata / Bresaola / Nueces / Aceitunas | H10: BUFALATA | I10: Mesclun / Burrata / Bresaola / Noix / Olives | J10: BUFALATA | K10: Mixed salad leaves / Burrata / Bresaola / Walnuts / Olives | L10: 16 | M10: 0 | N10: =L10+M10 -> 16 | O10: TRUE | P10: TRUE | Q10: TRUE
A11: BC-010 | B11: 10 | C11: amanides | D11: CÈSAR | E11: Enciam / pollastre / crostons / cherry / parmesà / salsa cèsar | F11: César | G11: Lechuga / Pollo / Picatostes / Tomates cherry / Parmesano / Salsa César | H11: César | I11: Laitue / Poulet / Croûtons / Tomates cerises / Parmesan / Sauce César | J11: Caesar | K11: Lettuce / Chicken / Croutons / Cherry tomatoes / Parmesan / Caesar dressing | L11: 16 | M11: 0 | N11: =L11+M11 -> 16 | O11: TRUE | P11: TRUE | Q11: TRUE
A12: BC-011 | B12: 11 | C12: amanides | D12: CABRA | E12: Mesclum / cherry / escalivada / albergínia, pebre, ceba / nous / cabra / balsàmic | F12: Queso de cabra | G12: Mezcla de hojas verdes / Tomates cherry / Escalivada / Berenjena, pimiento, cebolla / Nueces / Queso de cabra / Vinagre balsámico | H12: Chèvre | I12: Mesclun / Tomates cerises / Légumes grillés / Aubergine, poivron, oignon / Noix / Fromage de chèvre / Vinaigre balsamique | J12: Goat cheese | K12: Mixed salad leaves / Cherry tomatoes / Roasted vegetables / Aubergine, pepper, onion / Walnuts / Goat cheese / Balsamic dressing | L12: 16 | M12: 0 | N12: =L12+M12 -> 16 | O12: TRUE | P12: TRUE | Q12: TRUE
A13: BC-012 | B13: 12 | C13: amanides | D13: LUNA CAPRESE | E13: Tomàquet / mozzarella / salsa pesto / ruca / salsa mòdena | F13: LUNA CAPRESE | G13: Tomate / Mozzarella / Salsa pesto / Rúcula / Salsa de Módena | H13: LUNA CAPRESE | I13: Tomate / Mozzarella / Sauce pesto / Roquette / Sauce balsamique de Modène | J13: LUNA CAPRESE | K13: Tomato / Mozzarella / Pesto sauce / Rocket / Modena balsamic dressing | L13: 15.5 | M13: 0 | N13: =L13+M13 -> 15.5 | O13: TRUE | P13: TRUE | Q13: TRUE
A14: BC-013 | B14: 13 | C14: sopes | D14: SOPA DE LLENTIES | F14: Sopa de lentejas | H14: Soupe de lentilles | J14: Lentil soup | L14: 6 | M14: 0 | N14: =L14+M14 -> 6 | O14: TRUE | P14: TRUE | Q14: FALSE
A15: BC-014 | B15: 14 | C15: sopes | D15: SOPA DE BROCOLI | F15: Sopa de brócoli | H15: Soupe de brocoli | J15: Broccoli soup | L15: 6 | M15: 0 | N15: =L15+M15 -> 6 | O15: TRUE | P15: TRUE | Q15: FALSE
A16: BC-015 | B16: 15 | C16: carn | D16: CARPACCIO DE BOU | F16: Carpaccio de buey | H16: Carpaccio de bœuf | J16: Beef carpaccio | L16: 15 | M16: 0 | N16: =L16+M16 -> 15 | O16: TRUE | P16: TRUE | Q16: FALSE
A17: BC-016 | B17: 16 | C17: carn | D17: ENTRECOT DE BOU | F17: Entrecot de buey | H17: Entrecôte de bœuf | J17: Beef entrecôte | L17: 8.5 | M17: 0 | N17: =L17+M17 -> 8.5 | O17: TRUE | P17: TRUE | Q17: FALSE
A18: BC-017 | B18: 17 | C18: carn | D18: EMBOTITS ITALIANS | E18: Bresaola / salami / mortadel·la de tòfona / mortadel·la de pistatxos / la piatta piccante | F18: Embutidos italianos | G18: Bresaola / Salami / Mortadela de trufa / Mortadela de pistachos / La piatta piccante | H18: Charcuteries italiennes | I18: Bresaola / Salami / Mortadelle à la truffe / Mortadelle à la pistache / La piatta piccante | J18: Italian cured meats | K18: Bresaola / Salami / Truffle mortadella / Pistachio mortadella / La piatta piccante | L18: 22.5 | M18: 0 | N18: =L18+M18 -> 22.5 | O18: TRUE | P18: TRUE | Q18: TRUE
A19: BC-018 | B19: 18 | C19: pasta | D19: BIGOLI ALLA NAPOLITANA | E19: Pasta amb tomàquets | F19: BIGOLI ALLA NAPOLITANA | G19: Pasta con tomates | H19: BIGOLI ALLA NAPOLITANA | I19: Pâtes à la tomate | J19: BIGOLI ALLA NAPOLITANA | K19: Pasta with tomatoes | L19: 9.5 | M19: 0 | N19: =L19+M19 -> 9.5 | O19: TRUE | P19: TRUE | Q19: TRUE
A20: BC-019 | B20: 19 | C20: pasta | D20: TAGLIATELLE TARTUFATA | E20: Amb crema de tòfona | F20: TAGLIATELLE TARTUFATA | G20: Con crema de trufa | H20: TAGLIATELLE TARTUFATA | I20: À la crème de truffe | J20: TAGLIATELLE TARTUFATA | K20: With truffle cream | L20: 14 | M20: 0 | N20: =L20+M20 -> 14 | O20: TRUE | P20: TRUE | Q20: TRUE
A21: BC-020 | B21: 20 | C21: pasta | D21: GARGANELLI ALL’ARRABBIATA | E21: Salsa picant tradicional casolana | F21: GARGANELLI ALL’ARRABBIATA | G21: Salsa picante tradicional casera | H21: GARGANELLI ALL’ARRABBIATA | I21: Sauce piquante traditionnelle maison | J21: GARGANELLI ALL’ARRABBIATA | K21: Traditional homemade spicy sauce | L21: 14 | M21: 0 | N21: =L21+M21 -> 14 | O21: TRUE | P21: TRUE | Q21: TRUE
A22: BC-021 | B22: 21 | C22: pasta | D22: SPAGHETTI RAGÚ ALLA BOLOGNESE | E22: Salsa casolana de carn d'Andorra | F22: SPAGHETTI RAGÚ ALLA BOLOGNESE | G22: Salsa casera con carne de Andorra | H22: SPAGHETTI RAGÚ ALLA BOLOGNESE | I22: Sauce maison à la viande d’Andorre | J22: SPAGHETTI RAGÚ ALLA BOLOGNESE | K22: House-made sauce with Andorran meat | L22: 15.5 | M22: 0 | N22: =L22+M22 -> 15.5 | O22: TRUE | P22: TRUE | Q22: TRUE
A23: BC-022 | B23: 22 | C23: pasta | D23: TAGLIATELLE 4 FORMATGES | E23: Mozzarella / cabra / emmental / gorgonzola | F23: TAGLIATELLE 4 FORMATGES | G23: Mozzarella / Queso de cabra / Emmental / Gorgonzola | H23: TAGLIATELLE 4 FORMATGES | I23: Mozzarella / Fromage de chèvre / Emmental / Gorgonzola | J23: TAGLIATELLE 4 FORMATGES | K23: Mozzarella / Goat cheese / Emmental / Gorgonzola | L23: 15.5 | M23: 0 | N23: =L23+M23 -> 15.5 | O23: TRUE | P23: TRUE | Q23: FALSE
A24: BC-023 | B24: 23 | C24: pasta | D24: LINGUINE D’ALL I ALFÀBREGA AMB PESTO | E24: Salsa casolana d’alfàbrega de quilòmetre 0 | F24: Linguine de ajo y albahaca con pesto | G24: Salsa casera de albahaca local | H24: Linguine à l’ail et au basilic, au pesto | I24: Sauce maison au basilic local | J24: Garlic and basil linguine with pesto | K24: House-made sauce with locally grown basil | L24: 15.5 | M24: 0 | N24: =L24+M24 -> 15.5 | O24: TRUE | P24: TRUE | Q24: TRUE
A25: BC-024 | B25: 24 | C25: pasta | D25: BIGOLI ALLA CARBONARA | E25: Recepta tradicional amb ous i guanciale | F25: BIGOLI ALLA CARBONARA | G25: Receta tradicional con huevos y guanciale | H25: BIGOLI ALLA CARBONARA | I25: Recette traditionnelle aux œufs et au guanciale | J25: BIGOLI ALLA CARBONARA | K25: Traditional recipe with eggs and guanciale | L25: 17 | M25: 0 | N25: =L25+M25 -> 17 | O25: TRUE | P25: TRUE | Q25: TRUE
A26: BC-025 | B26: 25 | C26: pasta | D26: SPAGHETTI NERI FRUTTI DI MARE | E26: Salsa de tomàquets cherry / gambes / cloïsses / musclos | F26: SPAGHETTI NERI FRUTTI DI MARE | G26: Salsa de tomates cherry / gambas / almejas / mejillones | H26: SPAGHETTI NERI FRUTTI DI MARE | I26: Sauce aux tomates cerises / crevettes / palourdes / moules | J26: SPAGHETTI NERI FRUTTI DI MARE | K26: Cherry tomato sauce / prawns / clams / mussels | L26: 22 | M26: 0 | N26: =L26+M26 -> 22 | O26: TRUE | P26: TRUE | Q26: FALSE
A27: BC-026 | B27: 26 | C27: pasta_farcida | D27: RAVIOLIS DE BOLETS | E27: Servit amb salsa casolana de pesto | F27: Raviolis de setas | G27: Servidos con salsa pesto casera | H27: Raviolis aux champignons | I27: Servis avec sauce pesto maison | J27: Mushroom ravioli | K27: Served with homemade pesto sauce | L27: 17.5 | M27: 0 | N27: =L27+M27 -> 17.5 | O27: TRUE | P27: TRUE | Q27: TRUE
A28: BC-027 | B28: 27 | C28: pasta_farcida | D28: FIOCCHI AMB PERA I RICOTTA | E28: Servit amb crema de carbassa casolana | F28: FIOCCHI AMB PERA I RICOTTA | G28: Servidos con crema de calabaza casera | H28: FIOCCHI AMB PERA I RICOTTA | I28: Servis avec crème de potiron maison | J28: FIOCCHI AMB PERA I RICOTTA | K28: Served with homemade pumpkin cream | L28: 17 | M28: 0 | N28: =L28+M28 -> 17 | O28: TRUE | P28: TRUE | Q28: FALSE
A29: BC-028 | B29: 28 | C29: pasta_farcida | D29: CANELONS DE CARN | E29: Canelons fets per nosaltres servits amb salsa boloñesa casolana | F29: Canelones de carne | G29: Canelones caseros con salsa boloñesa casera | H29: Cannellonis à la viande | I29: Cannellonis maison à la sauce bolognaise | J29: Meat cannelloni | K29: Homemade cannelloni with Bolognese sauce | L29: 13.5 | M29: 0 | N29: =L29+M29 -> 13.5 | O29: TRUE | P29: TRUE | Q29: TRUE
... A48: BC-047 | B48: 47 | C48: pizzes_blanques | D48: CARBONARA | E48: Mozzarella / nata / guanciale / ceba / ou / parmesà | F48: CARBONARA | G48: Mozzarella / Nata / Guanciale / Cebolla / Huevo / Parmesano | H48: CARBONARA | I48: Mozzarella / Crème fraîche / Guanciale / Oignon / Œuf / Parmesan | J48: CARBONARA | K48: Mozzarella / Cream / Guanciale / Onion / Egg / Parmesan | L48: 16 | M48: 0 | N48: =L48+M48 -> 16 | O48: TRUE | P48: TRUE | Q48: TRUE
A49: BC-048 | B49: 48 | C49: postres | D49: TIRAMISÚ CLÀSSIC | F49: Tiramisú clásico | H49: Tiramisu classique | J49: Classic tiramisu | L49: 7 | M49: 0 | N49: =L49+M49 -> 7 | O49: TRUE | P49: TRUE | Q49: TRUE
A50: BC-049 | B50: 49 | C50: postres | D50: TIRAMISÚ DE FESTUCS | F50: Tiramisú de pistacho | H50: Tiramisu à la pistache | J50: Pistachio tiramisu | L50: 8 | M50: 0 | N50: =L50+M50 -> 8 | O50: TRUE | P50: TRUE | Q50: TRUE
A51: BC-050 | B51: 50 | C51: postres | D51: GELAT ARTESANAL | F51: Helado artesanal | H51: Glace artisanale | J51: Artisan ice cream | L51: 5 | M51: 0 | N51: =L51+M51 -> 5 | O51: TRUE | P51: TRUE | Q51: FALSE
A52: BC-051 | B52: 51 | C52: postres | D52: PANNA COTTA | E52: De romaní amb ginebra i préssec | F52: PANNA COTTA | G52: De romero con ginebra y melocotón | H52: PANNA COTTA | I52: Au romarin, gin et pêche | J52: PANNA COTTA | K52: Rosemary panna cotta with gin and peach | L52: 6.5 | M52: 0 | N52: =L52+M52 -> 6.5 | O52: TRUE | P52: TRUE | Q52: TRUE
A53: BC-052 | B53: 52 | C53: postres | D53: COULANT DE XOCOLATA | F53: Coulant de chocolate | H53: Coulant au chocolat | J53: Chocolate fondant | L53: 5 | M53: 0 | N53: =L53+M53 -> 5 | O53: TRUE | P53: TRUE | Q53: TRUE
A54: BC-053 | B54: 53 | C54: postres | D54: MADUIXES AL PEBRE | F54: Fresas a la pimienta | H54: Fraises au poivre | J54: Strawberries with pepper | L54: 12.5 | M54: 0 | N54: =L54+M54 -> 12.5 | O54: TRUE | P54: TRUE | Q54: FALSE
A55: BC-054 | B55: 54 | C55: postres | D55: CALZONE DOLÇA | F55: Calzone dulce | H55: Calzone sucrée | J55: Sweet calzone | L55: 10 | M55: 0 | N55: =L55+M55 -> 10 | O55: TRUE | P55: TRUE | Q55: TRUE
A56: BC-055 | B56: 55 | C56: postres | D56: AFFOGATO SENSE AMARETO | F56: Affogato sin amaretto | H56: Affogato sans amaretto | J56: Affogato without amaretto | L56: 6.5 | M56: 0 | N56: =L56+M56 -> 6.5 | O56: TRUE | P56: TRUE | Q56: FALSE
A57: BC-056 | B57: 56 | C57: postres | D57: AFFOGATO AMB AMARETTO | F57: Affogato con amaretto | H57: Affogato avec amaretto | J57: Affogato with amaretto | L57: 8.5 | M57: 0 | N57: =L57+M57 -> 8.5 | O57: TRUE | P57: TRUE | Q57: FALSE
A58: BC-057 | B58: 57 | C58: cafe_te | D58: CAFÈ SOL | F58: Café solo | H58: Café expresso | J58: Espresso | L58: 1.5 | M58: 0 | N58: =L58+M58 -> 1.5 | O58: TRUE | P58: TRUE | Q58: FALSE
...

Sheet CONTROL
A1: BELLA CIAO | PANEL DE CARTAS
A2: GESTIÓN CORPORATIVA · SOLO SHEETS
A3: Carta seleccionada | B3: DELIVERY
A4: Idioma de visualización | B4: CAT
A6: CANALES | B6: RESTAURANTE · WEB · DELIVERY/TAKE AWAY
A7: PRECIO | B7: Restaurante y web igual. Delivery = base + incremento en €.
A8: PRODUCTOS | B8: Activar/desactivar desde MAESTRA, columnas O · P · Q
A9: IMÁGENES | B9: Introducir URL en MAESTRA, columna R
A10: VALIDACIÓN | B10: Datos en revisión: no publicar hasta validación.
A11: FUENTE | B11: Cartas V2 de Bella Ciao, conservadas en Drive.

Sheet VISTA
A1: ID | B1: Categoría | C1: Producto | D1: Ingredientes / detalle | E1: Precio (€) | F1: Imagen URL
A2: =IFERROR(__xludf.DUMMYFUNCTION("IF(CONTROL!B3=""TODAS"",IFERROR(FILTER(HSTACK(MAESTRA!A2:A200,MAESTRA!C2:C200,IF(CONTROL!$B$4=""CAT"",MAESTRA!D2:D200,IF(CONTROL!$B$4=""ES"",MAESTRA!F2:F200,IF(CONTROL!$B$4=""FR"",MAESTRA!H2:H200,MAESTRA!J2:J200))),IF(CONTROL!$B$4=""CAT"",MAESTRA!E2:E200,"&"IF(CONTROL!$B$4=""ES"",MAESTRA!G2:G200,IF(CONTROL!$B$4=""FR"",MAESTRA!I2:I200,MAESTRA!K2:K200))),MAESTRA!L2:L200,MAESTRA!R2:R200),MAESTRA!A2:A200<>"""",MAESTRA!A2:A200<>""""),""""),IF(CONTROL!B3=""RESTAURANTE"",IFERROR(FILTER(HSTACK(MAESTRA!A2:A200,MAESTR"&"A!C2:C200,IF(CONTROL!$B$4=""CAT"",MAESTRA!D2:D200,IF(CONTROL!$B$4=""ES"",MAESTRA!F2:F200,IF(CONTROL!$B$4=""FR"",MAESTRA!H2:H200,MAESTRA!J2:J200))),IF(CONTROL!$B$4=""CAT"",MAESTRA!E2:E200,IF(CONTROL!$B$4=""ES"",MAESTRA!G2:G200,IF(CONTROL!$B$4=""FR"",MAESTR"&"A!I2:I200,MAESTRA!K2:K200))),MAESTRA!L2:L200,MAESTRA!R2:R200),MAESTRA!A2:A200<>"""",MAESTRA!O2:O200=TRUE),""""),IF(CONTROL!B3=""DELIVERY"",IFERROR(FILTER(HSTACK(MAESTRA!A2:A200,MAESTRA!C2:C200,IF(CONTROL!$B$4=""CAT"",MAESTRA!D2:D200,IF(CONTROL!$B$4=""ES"""&",MAESTRA!F2:F200,IF(CONTROL!$B$4=""FR"",MAESTRA!H2:H200,MAESTRA!J2:J200))),IF(CONTROL!$B$4=""CAT"",MAESTRA!E2:E200,IF(CONTROL!$B$4=""ES"",MAESTRA!G2:G200,IF(CONTROL!$B$4=""FR"",MAESTRA!I2:I200,MAESTRA!K2:K200))),MAESTRA!N2:N200,MAESTRA!R2:R200),MAESTRA!A2"&":A200<>"""",MAESTRA!Q2:Q200=TRUE),""""),IFERROR(FILTER(HSTACK(MAESTRA!A2:A200,MAESTRA!C2:C200,IF(CONTROL!$B$4=""CAT"",MAESTRA!D2:D200,IF(CONTROL!$B$4=""ES"",MAESTRA!F2:F200,IF(CONTROL!$B$4=""FR"",MAESTRA!H2:H200,MAESTRA!J2:J200))),IF(CONTROL!$B$4=""CAT"","&"MAESTRA!E2:E200,IF(CONTROL!$B$4=""ES"",MAESTRA!G2:G200,IF(CONTROL!$B$4=""FR"",MAESTRA!I2:I200,MAESTRA!K2:K200))),MAESTRA!L2:L200,MAESTRA!R2:R200),MAESTRA!A2:A200<>"""",MAESTRA!P2:P200=TRUE),""""))))"),"BC-001") -> BC-001 | B2: =IFERROR(__xludf.DUMMYFUNCTION("""COMPUTED_VALUE"""),"entrants") -> entrants | C2: =IFERROR(__xludf.DUMMYFUNCTION("""COMPUTED_VALUE"""),"PA DE PIZZA") -> PA DE PIZZA | D2: =IFERROR(__xludf.DUMMYFUNCTION("""COMPUTED_VALUE"""),"Massa normal / integral") -> Massa normal / integral | E2: =IFERROR(__xludf.DUMMYFUNCTION("""COMPUTED_VALUE"""),5.0) -> 5 | F2: =IFERROR(__xludf.DUMMYFUNCTION("""COMPUTED_VALUE"""),"")
A3: =IFERROR(__xludf.DUMMYFUNCTION("""COMPUTED_VALUE"""),"BC-002") -> BC-002 | B3: =IFERROR(__xludf.DUMMYFUNCTION("""COMPUTED_VALUE"""),"entrants") -> entrants | C3: =IFERROR(__xludf.DUMMYFUNCTION("""COMPUTED_VALUE"""),"FOCACCIA") -> FOCACCIA | D3: =IFERROR(__xludf.DUMMYFUNCTION("""COMPUTED_VALUE"""),"") | E3: =IFERROR(__xludf.DUMMYFUNCTION("""COMPUTED_VALUE"""),5.0) -> 5 | F3: =IFERROR(__xludf.DUMMYFUNCTION("""COMPUTED_VALUE"""),"")
A4: =IFERROR(__xludf.DUMMYFUNCTION("""COMPUTED_VALUE"""),"BC-003") -> BC-003 | B4: =IFERROR(__xludf.DUMMYFUNCTION("""COMPUTED_VALUE"""),"entrants") -> entrants | C4: =IFERROR(__xludf.DUMMYFUNCTION("""COMPUTED_VALUE"""),"PROVOLONE") -> PROVOLONE | D4: =IFERROR(__xludf.DUMMYFUNCTION("""COMPUTED_VALUE"""),"") | E4: =IFERROR(__xludf.DUMMYFUNCTION("""COMPUTED_VALUE"""),10.0) -> 10 | F4: =IFERROR(__xludf.DUMMYFUNCTION("""COMPUTED_VALUE"""),"")
A5: =IFERROR(__xludf.DUMMYFUNCTION("""COMPUTED_VALUE"""),"BC-009") -> BC-009 | B5: =IFERROR(__xludf.DUMMYFUNCTION("""COMPUTED_VALUE"""),"amanides") -> amanides | C5: =IFERROR(__xludf.DUMMYFUNCTION("""COMPUTED_VALUE"""),"BUFALATA") -> BUFALATA | D5: =IFERROR(__xludf.DUMMYFUNCTION("""COMPUTED_VALUE"""),"Mesclum / burrata / bresaola / nous / olives") -> Mesclum / burrata / bresaola / nous / olives | E5: =IFERROR(__xludf.DUMMYFUNCTION("""COMPUTED_VALUE"""),16.0) -> 16 | F5: =IFERROR(__xludf.DUMMYFUNCTION("""COMPUTED_VALUE"""),"")
A6: =IFERROR(__xludf.DUMMYFUNCTION("""COMPUTED_VALUE"""),"BC-010") -> BC-010 | B6: =IFERROR(__xludf.DUMMYFUNCTION("""COMPUTED_VALUE"""),"amanides") -> amanides | C6: =IFERROR(__xludf.DUMMYFUNCTION("""COMPUTED_VALUE"""),"CÈSAR") -> CÈSAR | D6: =IFERROR(__xludf.DUMMYFUNCTION("""COMPUTED_VALUE"""),"Enciam / pollastre / crostons / cherry / parmesà / salsa cèsar") -> Enciam / pollastre / crostons / cherry / parmesà / salsa cèsar | E6: =IFERROR(__xludf.DUMMYFUNCTION("""COMPUTED_VALUE"""),16.0) -> 16 | F6: =IFERROR(__xludf.DUMMYFUNCTION("""COMPUTED_VALUE"""),"")
A7: =IFERROR(__xludf.DUMMYFUNCTION("""COMPUTED_VALUE"""),"BC-011") -> BC-011 | B7: =IFERROR(__xludf.DUMMYFUNCTION("""COMPUTED_VALUE"""),"amanides") -> amanides | C7: =IFERROR(__xludf.DUMMYFUNCTION("""COMPUTED_VALUE"""),"CABRA") -> CABRA | D7: =IFERROR(__xludf.DUMMYFUNCTION("""COMPUTED_VALUE"""),"Mesclum / cherry / escalivada / albergínia, pebre, ceba / nous / cabra / balsàmic") -> Mesclum / cherry / escalivada / albergínia, pebre, ceba / nous / cabra / balsàmic | E7: =IFERROR(__xludf.DUMMYFUNCTION("""COMPUTED_VALUE"""),16.0) -> 16 | F7: =IFERROR(__xludf.DUMMYFUNCTION("""COMPUTED_VALUE"""),"")
A8: =IFERROR(__xludf.DUMMYFUNCTION("""COMPUTED_VALUE"""),"BC-012") -> BC-012 | B8: =IFERROR(__xludf.DUMMYFUNCTION("""COMPUTED_VALUE"""),"amanides") -> amanides | C8: =IFERROR(__xludf.DUMMYFUNCTION("""COMPUTED_VALUE"""),"LUNA CAPRESE") -> LUNA CAPRESE | D8: =IFERROR(__xludf.DUMMYFUNCTION("""COMPUTED_VALUE"""),"Tomàquet / mozzarella / salsa pesto / ruca / salsa mòdena") -> Tomàquet / mozzarella / salsa pesto / ruca / salsa mòdena | E8: =IFERROR(__xludf.DUMMYFUNCTION("""COMPUTED_VALUE"""),15.5) -> 15.5 | F8: =IFERROR(__xludf.DUMMYFUNCTION("""COMPUTED_VALUE"""),"")
A9: =IFERROR(__xludf.DUMMYFUNCTION("""COMPUTED_VALUE"""),"BC-017") -> BC-017 | B9: =IFERROR(__xludf.DUMMYFUNCTION("""COMPUTED_VALUE"""),"carn") -> carn | C9: =IFERROR(__xludf.DUMMYFUNCTION("""COMPUTED_VALUE"""),"EMBOTITS ITALIANS") -> EMBOTITS ITALIANS | D9: =IFERROR(__xludf.DUMMYFUNCTION("""COMPUTED_VALUE"""),"Bresaola / salami / mortadel·la de tòfona / mortadel·la de pistatxos / la piatta piccante") -> Bresaola / salami / mortadel·la de tòfona / mortadel·la de pistatxos / la piatta piccante | E9: =IFERROR(__xludf.DUMMYFUNCTION("""COMPUTED_VALUE"""),22.5) -> 22.5 | F9: =IFERROR(__xludf.DUMMYFUNCTION("""COMPUTED_VALUE"""),"")
A10: =IFERROR(__xludf.DUMMYFUNCTION("""COMPUTED_VALUE"""),"BC-018") -> BC-018 | B10: =IFERROR(__xludf.DUMMYFUNCTION("""COMPUTED_VALUE"""),"pasta") -> pasta | C10: =IFERROR(__xludf.DUMMYFUNCTION("""COMPUTED_VALUE"""),"BIGOLI ALLA NAPOLITANA") -> BIGOLI ALLA NAPOLITANA | D10: =IFERROR(__xludf.DUMMYFUNCTION("""COMPUTED_VALUE"""),"Pasta amb tomàquets") -> Pasta amb tomàquets | E10: =IFERROR(__xludf.DUMMYFUNCTION("""COMPUTED_VALUE"""),9.5) -> 9.5 | F10: =IFERROR(__xludf.DUMMYFUNCTION("""COMPUTED_VALUE"""),"")
A11: =IFERROR(__xludf.DUMMYFUNCTION("""COMPUTED_VALUE"""),"BC-019") -> BC-019 | B11: =IFERROR(__xludf.DUMMYFUNCTION("""COMPUTED_VALUE"""),"pasta") -> pasta | C11: =IFERROR(__xludf.DUMMYFUNCTION("""COMPUTED_VALUE"""),"TAGLIATELLE TARTUFATA") -> TAGLIATELLE TARTUFATA | D11: =IFERROR(__xludf.DUMMYFUNCTION("""COMPUTED_VALUE"""),"Amb crema de tòfona") -> Amb crema de tòfona | E11: =IFERROR(__xludf.DUMMYFUNCTION("""COMPUTED_VALUE"""),14.0) -> 14 | F11: =IFERROR(__xludf.DUMMYFUNCTION("""COMPUTED_VALUE"""),"")
A12: =IFERROR(__xludf.DUMMYFUNCTION("""COMPUTED_VALUE"""),"BC-020") -> BC-020 | B12: =IFERROR(__xludf.DUMMYFUNCTION("""COMPUTED_VALUE"""),"pasta") -> pasta | C12: =IFERROR(__xludf.DUMMYFUNCTION("""COMPUTED_VALUE"""),"GARGANELLI ALL’ARRABBIATA") -> GARGANELLI ALL’ARRABBIATA | D12: =IFERROR(__xludf.DUMMYFUNCTION("""COMPUTED_VALUE"""),"Salsa picant tradicional casolana") -> Salsa picant tradicional casolana | E12: =IFERROR(__xludf.DUMMYFUNCTION("""COMPUTED_VALUE"""),14.0) -> 14 | F12: =IFERROR(__xludf.DUMMYFUNCTION("""COMPUTED_VALUE"""),"")
A13: =IFERROR(__xludf.DUMMYFUNCTION("""COMPUTED_VALUE"""),"BC-021") -> BC-021 | B13: =IFERROR(__xludf.DUMMYFUNCTION("""COMPUTED_VALUE"""),"pasta") -> pasta | C13: =IFERROR(__xludf.DUMMYFUNCTION("""COMPUTED_VALUE"""),"SPAGHETTI RAGÚ ALLA BOLOGNESE") -> SPAGHETTI RAGÚ ALLA BOLOGNESE | D13: =IFERROR(__xludf.DUMMYFUNCTION("""COMPUTED_VALUE"""),"Salsa casolana de carn d'Andorra") -> Salsa casolana de carn d'Andorra | E13: =IFERROR(__xludf.DUMMYFUNCTION("""COMPUTED_VALUE"""),15.5) -> 15.5 | F13: =IFERROR(__xludf.DUMMYFUNCTION("""COMPUTED_VALUE"""),"")
A14: =IFERROR(__xludf.DUMMYFUNCTION("""COMPUTED_VALUE"""),"BC-023") -> BC-023 | B14: =IFERROR(__xludf.DUMMYFUNCTION("""COMPUTED_VALUE"""),"pasta") -> pasta | C14: =IFERROR(__xludf.DUMMYFUNCTION("""COMPUTED_VALUE"""),"LINGUINE D’ALL I ALFÀBREGA AMB PESTO") -> LINGUINE D’ALL I ALFÀBREGA AMB PESTO | D14: =IFERROR(__xludf.DUMMYFUNCTION("""COMPUTED_VALUE"""),"Salsa casolana d’alfàbrega de quilòmetre 0") -> Salsa casolana d’alfàbrega de quilòmetre 0 | E14: =IFERROR(__xludf.DUMMYFUNCTION("""COMPUTED_VALUE"""),15.5) -> 15.5 | F14: =IFERROR(__xludf.DUMMYFUNCTION("""COMPUTED_VALUE"""),"")
A15: =IFERROR(__xludf.DUMMYFUNCTION("""COMPUTED_VALUE"""),"BC-024") -> BC-024 | B15: =IFERROR(__xludf.DUMMYFUNCTION("""COMPUTED_VALUE"""),"pasta") -> pasta | C15: =IFERROR(__xludf.DUMMYFUNCTION("""COMPUTED_VALUE"""),"BIGOLI ALLA CARBONARA") -> BIGOLI ALLA CARBONARA | D15: =IFERROR(__xludf.DUMMYFUNCTION("""COMPUTED_VALUE"""),"Recepta tradicional amb ous i guanciale") -> Recepta tradicional amb ous i guanciale | E15: =IFERROR(__xludf.DUMMYFUNCTION("""COMPUTED_VALUE"""),17.0) -> 17 | F15: =IFERROR(__xludf.DUMMYFUNCTION("""COMPUTED_VALUE"""),"")
A16: =IFERROR(__xludf.DUMMYFUNCTION("""COMPUTED_VALUE"""),"BC-026") -> BC-026 | B16: =IFERROR(__xludf.DUMMYFUNCTION("""COMPUTED_VALUE"""),"pasta_farcida") -> pasta_farcida | C16: =IFERROR(__xludf.DUMMYFUNCTION("""COMPUTED_VALUE"""),"RAVIOLIS DE BOLETS") -> RAVIOLIS DE BOLETS | D16: =IFERROR(__xludf.DUMMYFUNCTION("""COMPUTED_VALUE"""),"Servit amb salsa casolana de pesto") -> Servit amb salsa casolana de pesto | E16: =IFERROR(__xludf.DUMMYFUNCTION("""COMPUTED_VALUE"""),17.5) -> 17.5 | F16: =IFERROR(__xludf.DUMMYFUNCTION("""COMPUTED_VALUE"""),"")
A17: =IFERROR(__xludf.DUMMYFUNCTION("""COMPUTED_VALUE"""),"BC-028") -> BC-028 | B17: =IFERROR(__xludf.DUMMYFUNCTION("""COMPUTED_VALUE"""),"pasta_farcida") -> pasta_farcida | C17: =IFERROR(__xludf.DUMMYFUNCTION("""COMPUTED_VALUE"""),"CANELONS DE CARN") -> CANELONS DE CARN | D17: =IFERROR(__xludf.DUMMYFUNCTION("""COMPUTED_VALUE"""),"Canelons fets per nosaltres servits amb salsa boloñesa casolana") -> Canelons fets per nosaltres servits amb salsa boloñesa casolana | E17: =IFERROR(__xludf.DUMMYFUNCTION("""COMPUTED_VALUE"""),13.5) -> 13.5 | F17: =IFERROR(__xludf.DUMMYFUNCTION("""COMPUTED_VALUE"""),"")
A18: =IFERROR(__xludf.DUMMYFUNCTION("""COMPUTED_VALUE"""),"BC-029") -> BC-029 | B18: =IFERROR(__xludf.DUMMYFUNCTION("""COMPUTED_VALUE"""),"pasta_farcida") -> pasta_farcida | C18: =IFERROR(__xludf.DUMMYFUNCTION("""COMPUTED_VALUE"""),"NYOQUIS") -> NYOQUIS | D18: =IFERROR(__xludf.DUMMYFUNCTION("""COMPUTED_VALUE"""),"Crema de tomàquet fresc i stracciatella") -> Crema de tomàquet fresc i stracciatella | E18: =IFERROR(__xludf.DUMMYFUNCTION("""COMPUTED_VALUE"""),16.0) -> 16 | F18: =IFERROR(__xludf.DUMMYFUNCTION("""COMPUTED_VALUE"""),"")
A19: =IFERROR(__xludf.DUMMYFUNCTION("""COMPUTED_VALUE"""),"BC-030") -> BC-030 | B19: =IFERROR(__xludf.DUMMYFUNCTION("""COMPUTED_VALUE"""),"pasta_farcida") -> pasta_farcida | C19: =IFERROR(__xludf.DUMMYFUNCTION("""COMPUTED_VALUE"""),"LASANYA BOLONYESA") -> LASANYA BOLONYESA | D19: =IFERROR(__xludf.DUMMYFUNCTION("""COMPUTED_VALUE"""),"Feta per nosaltres / salsa bolonyesa casolana") -> Feta per nosaltres / salsa bolonyesa casolana | E19: =IFERROR(__xludf.DUMMYFUNCTION("""COMPUTED_VALUE"""),15.5) -> 15.5 | F19: =IFERROR(__xludf.DUMMYFUNCTION("""COMPUTED_VALUE"""),"")
A20: =IFERROR(__xludf.DUMMYFUNCTION("""COMPUTED_VALUE"""),"BC-031") -> BC-031 | B20: =IFERROR(__xludf.DUMMYFUNCTION("""COMPUTED_VALUE"""),"pasta_farcida") -> pasta_farcida | C20: =IFERROR(__xludf.DUMMYFUNCTION("""COMPUTED_VALUE"""),"RISOTTO DE BOLETS") -> RISOTTO DE BOLETS | D20: =IFERROR(__xludf.DUMMYFUNCTION("""COMPUTED_VALUE"""),"Amb crema de tòfona") -> Amb crema de tòfona | E20: =IFERROR(__xludf.DUMMYFUNCTION("""COMPUTED_VALUE"""),19.0) -> 19 | F20: =IFERROR(__xludf.DUMMYFUNCTION("""COMPUTED_VALUE"""),"")
A21: =IFERROR(__xludf.DUMMYFUNCTION("""COMPUTED_VALUE"""),"BC-032") -> BC-032 | B21: =IFERROR(__xludf.DUMMYFUNCTION("""COMPUTED_VALUE"""),"pizzes") -> pizzes | C21: =IFERROR(__xludf.DUMMYFUNCTION("""COMPUTED_VALUE"""),"MARGARITA") -> MARGARITA | D21: =IFERROR(__xludf.DUMMYFUNCTION("""COMPUTED_VALUE"""),"Tomàquet / mozzarella") -> Tomàquet / mozzarella | E21: =IFERROR(__xludf.DUMMYFUNCTION("""COMPUTED_VALUE"""),12.0) -> 12 | F21: =IFERROR(__xludf.DUMMYFUNCTION("""COMPUTED_VALUE"""),"")
A22: =IFERROR(__xludf.DUMMYFUNCTION("""COMPUTED_VALUE"""),"BC-033") -> BC-033 | B22: =IFERROR(__xludf.DUMMYFUNCTION("""COMPUTED_VALUE"""),"pizzes") -> pizzes | C22: =IFERROR(__xludf.DUMMYFUNCTION("""COMPUTED_VALUE"""),"PROSCIUTO") -> PROSCIUTO | D22: =IFERROR(__xludf.DUMMYFUNCTION("""COMPUTED_VALUE"""),"Tomàquet / mozzarella / pernil dolç") -> Tomàquet / mozzarella / pernil dolç | E22: =IFERROR(__xludf.DUMMYFUNCTION("""COMPUTED_VALUE"""),14.5) -> 14.5 | F22: =IFERROR(__xludf.DUMMYFUNCTION("""COMPUTED_VALUE"""),"")
A23: =IFERROR(__xludf.DUMMYFUNCTION("""COMPUTED_VALUE"""),"BC-034") -> BC-034 | B23: =IFERROR(__xludf.DUMMYFUNCTION("""COMPUTED_VALUE"""),"pizzes") -> pizzes | C23: =IFERROR(__xludf.DUMMYFUNCTION("""COMPUTED_VALUE"""),"REGINA") -> REGINA | D23: =IFERROR(__xludf.DUMMYFUNCTION("""COMPUTED_VALUE"""),"Tomàquet / mozzarella / pernil dolç / xampinyons") -> Tomàquet / mozzarella / pernil dolç / xampinyons | E23: =IFERROR(__xludf.DUMMYFUNCTION("""COMPUTED_VALUE"""),15.0) -> 15 | F23: =IFERROR(__xludf.DUMMYFUNCTION("""COMPUTED_VALUE"""),"")
A24: =IFERROR(__xludf.DUMMYFUNCTION("""COMPUTED_VALUE"""),"BC-035") -> BC-035 | B24: =IFERROR(__xludf.DUMMYFUNCTION("""COMPUTED_VALUE"""),"pizzes") -> pizzes | C24: =IFERROR(__xludf.DUMMYFUNCTION("""COMPUTED_VALUE"""),"CALZONE") -> CALZONE | D24: =IFERROR(__xludf.DUMMYFUNCTION("""COMPUTED_VALUE"""),"Tomàquet / mozzarella / pernil dolç / ou") -> Tomàquet / mozzarella / pernil dolç / ou | E24: =IFERROR(__xludf.DUMMYFUNCTION("""COMPUTED_VALUE"""),17.0) -> 17 | F24: =IFERROR(__xludf.DUMMYFUNCTION("""COMPUTED_VALUE"""),"")
A25: =IFERROR(__xludf.DUMMYFUNCTION("""COMPUTED_VALUE"""),"BC-036") -> BC-036 | B25: =IFERROR(__xludf.DUMMYFUNCTION("""COMPUTED_VALUE"""),"pizzes") -> pizzes | C25: =IFERROR(__xludf.DUMMYFUNCTION("""COMPUTED_VALUE"""),"PEPPERONI") -> PEPPERONI | D25: =IFERROR(__xludf.DUMMYFUNCTION("""COMPUTED_VALUE"""),"Tomàquet / mozzarella / pepperoni / bitxo verd") -> Tomàquet / mozzarella / pepperoni / bitxo verd | E25: =IFERROR(__xludf.DUMMYFUNCTION("""COMPUTED_VALUE"""),15.5) -> 15.5 | F25: =IFERROR(__xludf.DUMMYFUNCTION("""COMPUTED_VALUE"""),"")
A26: =IFERROR(__xludf.DUMMYFUNCTION("""COMPUTED_VALUE"""),"BC-037") -> BC-037 | B26: =IFERROR(__xludf.DUMMYFUNCTION("""COMPUTED_VALUE"""),"pizzes") -> pizzes | C26: =IFERROR(__xludf.DUMMYFUNCTION("""COMPUTED_VALUE"""),"CAPRESE") -> CAPRESE | D26: =IFERROR(__xludf.DUMMYFUNCTION("""COMPUTED_VALUE"""),"Tomàquet / mozzarella fresca / tomàquet sec casolà / alfàbrega") -> Tomàquet / mozzarella fresca / tomàquet sec casolà / alfàbrega | E26: =IFERROR(__xludf.DUMMYFUNCTION("""COMPUTED_VALUE"""),15.5) -> 15.5 | F26: =IFERROR(__xludf.DUMMYFUNCTION("""COMPUTED_VALUE"""),"")
A27: =IFERROR(__xludf.DUMMYFUNCTION("""COMPUTED_VALUE"""),"BC-039") -> BC-039 | B27: =IFERROR(__xludf.DUMMYFUNCTION("""COMPUTED_VALUE"""),"pizzes") -> pizzes | C27: =IFERROR(__xludf.DUMMYFUNCTION("""COMPUTED_VALUE"""),"IBÉRICA") -> IBÉRICA | D27: =IFERROR(__xludf.DUMMYFUNCTION("""COMPUTED_VALUE"""),"Tomàquet / mozzarella / pernil ibèric / parmesà / ruca") -> Tomàquet / mozzarella / pernil ibèric / parmesà / ruca | E27: =IFERROR(__xludf.DUMMYFUNCTION("""COMPUTED_VALUE"""),18.5) -> 18.5 | F27: =IFERROR(__xludf.DUMMYFUNCTION("""COMPUTED_VALUE"""),"")
A28: =IFERROR(__xludf.DUMMYFUNCTION("""COMPUTED_VALUE"""),"BC-040") -> BC-040 | B28: =IFERROR(__xludf.DUMMYFUNCTION("""COMPUTED_VALUE"""),"pizzes") -> pizzes | C28: =IFERROR(__xludf.DUMMYFUNCTION("""COMPUTED_VALUE"""),"4 ESTACIONS") -> 4 ESTACIONS | D28: =IFERROR(__xludf.DUMMYFUNCTION("""COMPUTED_VALUE"""),"Tomàquet / mozzarella / pernil dolç / xampinyons / carxofes / olives") -> Tomàquet / mozzarella / pernil dolç / xampinyons / carxofes / olives | E28: =IFERROR(__xludf.DUMMYFUNCTION("""COMPUTED_VALUE"""),16.0) -> 16 | F28: =IFERROR(__xludf.DUMMYFUNCTION("""COMPUTED_VALUE"""),"")
A29: =IFERROR(__xludf.DUMMYFUNCTION("""COMPUTED_VALUE"""),"BC-041") -> BC-041 | B29: =IFERROR(__xludf.DUMMYFUNCTION("""COMPUTED_VALUE"""),"pizzes") -> pizzes | C29: =IFERROR(__xludf.DUMMYFUNCTION("""COMPUTED_VALUE"""),"BELLA CIAO") -> BELLA CIAO | D29: =IFERROR(__xludf.DUMMYFUNCTION("""COMPUTED_VALUE"""),"Tomàquet / mozzarella / bologna / burrata / vinagreta de pistatxo") -> Tomàquet / mozzarella / bologna / burrata / vinagreta de pistatxo | E29: =IFERROR(__xludf.DUMMYFUNCTION("""COMPUTED_VALUE"""),17.5) -> 17.5 | F29: =IFERROR(__xludf.DUMMYFUNCTION("""COMPUTED_VALUE"""),"")
A30: =IFERROR(__xludf.DUMMYFUNCTION("""COMPUTED_VALUE"""),"BC-042") -> BC-042 | B30: =IFERROR(__xludf.DUMMYFUNCTION("""COMPUTED_VALUE"""),"pizzes") -> pizzes | C30: =IFERROR(__xludf.DUMMYFUNCTION("""COMPUTED_VALUE"""),"ITALIANA") -> ITALIANA | D30: =IFERROR(__xludf.DUMMYFUNCTION("""COMPUTED_VALUE"""),"Tomàquet / ruca / mozzarella / cherry / burrata / salsa pesto") -> Tomàquet / ruca / mozzarella / cherry / burrata / salsa pesto | E30: =IFERROR(__xludf.DUMMYFUNCTION("""COMPUTED_VALUE"""),18.0) -> 18 | F30: =IFERROR(__xludf.DUMMYFUNCTION("""COMPUTED_VALUE"""),"")
A31: =IFERROR(__xludf.DUMMYFUNCTION("""COMPUTED_VALUE"""),"BC-043") -> BC-043 | B31: =IFERROR(__xludf.DUMMYFUNCTION("""COMPUTED_VALUE"""),"pizzes") -> pizzes | C31: =IFERROR(__xludf.DUMMYFUNCTION("""COMPUTED_VALUE"""),"VEGETARIANA") -> VEGETARIANA | D31: =IFERROR(__xludf.DUMMYFUNCTION("""COMPUTED_VALUE"""),"Tomàquet / mozzarella / pebrot / carxofes / xampinyons / ceba") -> Tomàquet / mozzarella / pebrot / carxofes / xampinyons / ceba | E31: =IFERROR(__xludf.DUMMYFUNCTION("""COMPUTED_VALUE"""),16.5) -> 16.5 | F31: =IFERROR(__xludf.DUMMYFUNCTION("""COMPUTED_VALUE"""),"")
A32: =IFERROR(__xludf.DUMMYFUNCTION("""COMPUTED_VALUE"""),"BC-044") -> BC-044 | B32: =IFERROR(__xludf.DUMMYFUNCTION("""COMPUTED_VALUE"""),"pizzes_blanques") -> pizzes_blanques | C32: =IFERROR(__xludf.DUMMYFUNCTION("""COMPUTED_VALUE"""),"TARTUFATA") -> TARTUFATA | D32: =IFERROR(__xludf.DUMMYFUNCTION("""COMPUTED_VALUE"""),"Mozzarella / crema de tòfona / romaní / parmesà") -> Mozzarella / crema de tòfona / romaní / parmesà | E32: =IFERROR(__xludf.DUMMYFUNCTION("""COMPUTED_VALUE"""),15.5) -> 15.5 | F32: =IFERROR(__xludf.DUMMYFUNCTION("""COMPUTED_VALUE"""),"")
A33: =IFERROR(__xludf.DUMMYFUNCTION("""COMPUTED_VALUE"""),"BC-045") -> BC-045 | B33: =IFERROR(__xludf.DUMMYFUNCTION("""COMPUTED_VALUE"""),"pizzes_blanques") -> pizzes_blanques | C33: =IFERROR(__xludf.DUMMYFUNCTION("""COMPUTED_VALUE"""),"5 FORMATGES") -> 5 FORMATGES | D33: =IFERROR(__xludf.DUMMYFUNCTION("""COMPUTED_VALUE"""),"Mozzarella / cabra / emmental / roquefort / parmesà") -> Mozzarella / cabra / emmental / roquefort / parmesà | E33: =IFERROR(__xludf.DUMMYFUNCTION("""COMPUTED_VALUE"""),16.5) -> 16.5 | F33: =IFERROR(__xludf.DUMMYFUNCTION("""COMPUTED_VALUE"""),"")
A34: =IFERROR(__xludf.DUMMYFUNCTION("""COMPUTED_VALUE"""),"BC-047") -> BC-047 | B34: =IFERROR(__xludf.DUMMYFUNCTION("""COMPUTED_VALUE"""),"pizzes_blanques") -> pizzes_blanques | C34: =IFERROR(__xludf.DUMMYFUNCTION("""COMPUTED_VALUE"""),"CARBONARA") -> CARBONARA | D34: =IFERROR(__xludf.DUMMYFUNCTION("""COMPUTED_VALUE"""),"Mozzarella / nata / guanciale / ceba / ou / parmesà") -> Mozzarella / nata / guanciale / ceba / ou / parmesà | E34: =IFERROR(__xludf.DUMMYFUNCTION("""COMPUTED_VALUE"""),16.0) -> 16 | F34: =IFERROR(__xludf.DUMMYFUNCTION("""COMPUTED_VALUE"""),"")
A35: =IFERROR(__xludf.DUMMYFUNCTION("""COMPUTED_VALUE"""),"BC-048") -> BC-048 | B35: =IFERROR(__xludf.DUMMYFUNCTION("""COMPUTED_VALUE"""),"postres") -> postres | C35: =IFERROR(__xludf.DUMMYFUNCTION("""COMPUTED_VALUE"""),"TIRAMISÚ CLÀSSIC") -> TIRAMISÚ CLÀSSIC | D35: =IFERROR(__xludf.DUMMYFUNCTION("""COMPUTED_VALUE"""),"") | E35: =IFERROR(__xludf.DUMMYFUNCTION("""COMPUTED_VALUE"""),7.0) -> 7 | F35: =IFERROR(__xludf.DUMMYFUNCTION("""COMPUTED_VALUE"""),"")
A36: =IFERROR(__xludf.DUMMYFUNCTION("""COMPUTED_VALUE"""),"BC-049") -> BC-049 | B36: =IFERROR(__xludf.DUMMYFUNCTION("""COMPUTED_VALUE"""),"postres") -> postres | C36: =IFERROR(__xludf.DUMMYFUNCTION("""COMPUTED_VALUE"""),"TIRAMISÚ DE FESTUCS") -> TIRAMISÚ DE FESTUCS | D36: =IFERROR(__xludf.DUMMYFUNCTION("""COMPUTED_VALUE"""),"") | E36: =IFERROR(__xludf.DUMMYFUNCTION("""COMPUTED_VALUE"""),8.0) -> 8 | F36: =IFERROR(__xludf.DUMMYFUNCTION("""COMPUTED_VALUE"""),"")
A37: =IFERROR(__xludf.DUMMYFUNCTION("""COMPUTED_VALUE"""),"BC-051") -> BC-051 | B37: =IFERROR(__xludf.DUMMYFUNCTION("""COMPUTED_VALUE"""),"postres") -> postres | C37: =IFERROR(__xludf.DUMMYFUNCTION("""COMPUTED_VALUE"""),"PANNA COTTA") -> PANNA COTTA | D37: =IFERROR(__xludf.DUMMYFUNCTION("""COMPUTED_VALUE"""),"De romaní amb ginebra i préssec") -> De romaní amb ginebra i préssec | E37: =IFERROR(__xludf.DUMMYFUNCTION("""COMPUTED_VALUE"""),6.5) -> 6.5 | F37: =IFERROR(__xludf.DUMMYFUNCTION("""COMPUTED_VALUE"""),"")
A38: =IFERROR(__xludf.DUMMYFUNCTION("""COMPUTED_VALUE"""),"BC-052") -> BC-052 | B38: =IFERROR(__xludf.DUMMYFUNCTION("""COMPUTED_VALUE"""),"postres") -> postres | C38: =IFERROR(__xludf.DUMMYFUNCTION("""COMPUTED_VALUE"""),"COULANT DE XOCOLATA") -> COULANT DE XOCOLATA | D38: =IFERROR(__xludf.DUMMYFUNCTION("""COMPUTED_VALUE"""),"") | E38: =IFERROR(__xludf.DUMMYFUNCTION("""COMPUTED_VALUE"""),5.0) -> 5 | F38: =IFERROR(__xludf.DUMMYFUNCTION("""COMPUTED_VALUE"""),"")
A39: =IFERROR(__xludf.DUMMYFUNCTION("""COMPUTED_VALUE"""),"BC-054") -> BC-054 | B39: =IFERROR(__xludf.DUMMYFUNCTION("""COMPUTED_VALUE"""),"postres") -> postres | C39: =IFERROR(__xludf.DUMMYFUNCTION("""COMPUTED_VALUE"""),"CALZONE DOLÇA") -> CALZONE DOLÇA | D39: =IFERROR(__xludf.DUMMYFUNCTION("""COMPUTED_VALUE"""),"") | E39: =IFERROR(__xludf.DUMMYFUNCTION("""COMPUTED_VALUE"""),10.0) -> 10 | F39: =IFERROR(__xludf.DUMMYFUNCTION("""COMPUTED_VALUE"""),"")
A40: =IFERROR(__xludf.DUMMYFUNCTION("""COMPUTED_VALUE"""),"BC-067") -> BC-067 | B40: =IFERROR(__xludf.DUMMYFUNCTION("""COMPUTED_VALUE"""),"begudes") -> begudes | C40: =IFERROR(__xludf.DUMMYFUNCTION("""COMPUTED_VALUE"""),"REFRESCOS") -> REFRESCOS | D40: =IFERROR(__xludf.DUMMYFUNCTION("""COMPUTED_VALUE"""),"Coca-Cola / Fanta / Cola Zero / Nestea / Aquarius") -> Coca-Cola / Fanta / Cola Zero / Nestea / Aquarius | E40: =IFERROR(__xludf.DUMMYFUNCTION("""COMPUTED_VALUE"""),3.0) -> 3 | F40: =IFERROR(__xludf.DUMMYFUNCTION("""COMPUTED_VALUE"""),"")
...

Sheet RESTAURANTE
A1: ID | B1: Categoría | C1: Producto | D1: Ingredientes / detalle | E1: Precio (€) | F1: Imagen URL
A2: =IFERROR(__xludf.DUMMYFUNCTION("IFERROR(FILTER(HSTACK(MAESTRA!A2:A200,MAESTRA!C2:C200,IF(CONTROL!$B$4=""CAT"",MAESTRA!D2:D200,IF(CONTROL!$B$4=""ES"",MAESTRA!F2:F200,IF(CONTROL!$B$4=""FR"",MAESTRA!H2:H200,MAESTRA!J2:J200))),IF(CONTROL!$B$4=""CAT"",MAESTRA!E2:E200,IF(CONTROL!$B$4=""ES"",M"&"AESTRA!G2:G200,IF(CONTROL!$B$4=""FR"",MAESTRA!I2:I200,MAESTRA!K2:K200))),MAESTRA!L2:L200,MAESTRA!R2:R200),MAESTRA!A2:A200<>"""",MAESTRA!O2:O200=TRUE),"""")"),"BC-001") -> BC-001 | B2: =IFERROR(__xludf.DUMMYFUNCTION("""COMPUTED_VALUE"""),"entrants") -> entrants | C2: =IFERROR(__xludf.DUMMYFUNCTION("""COMPUTED_VALUE"""),"PA DE PIZZA") -> PA DE PIZZA | D2: =IFERROR(__xludf.DUMMYFUNCTION("""COMPUTED_VALUE"""),"Massa normal / integral") -> Massa normal / integral | E2: =IFERROR(__xludf.DUMMYFUNCTION("""COMPUTED_VALUE"""),5.0) -> 5 | F2: =IFERROR(__xludf.DUMMYFUNCTION("""COMPUTED_VALUE"""),"")
A3: =IFERROR(__xludf.DUMMYFUNCTION("""COMPUTED_VALUE"""),"BC-002") -> BC-002 | B3: =IFERROR(__xludf.DUMMYFUNCTION("""COMPUTED_VALUE"""),"entrants") -> entrants | C3: =IFERROR(__xludf.DUMMYFUNCTION("""COMPUTED_VALUE"""),"FOCACCIA") -> FOCACCIA | D3: =IFERROR(__xludf.DUMMYFUNCTION("""COMPUTED_VALUE"""),"") | E3: =IFERROR(__xludf.DUMMYFUNCTION("""COMPUTED_VALUE"""),5.0) -> 5 | F3: =IFERROR(__xludf.DUMMYFUNCTION("""COMPUTED_VALUE"""),"")
A4: =IFERROR(__xludf.DUMMYFUNCTION("""COMPUTED_VALUE"""),"BC-003") -> BC-003 | B4: =IFERROR(__xludf.DUMMYFUNCTION("""COMPUTED_VALUE"""),"entrants") -> entrants | C4: =IFERROR(__xludf.DUMMYFUNCTION("""COMPUTED_VALUE"""),"PROVOLONE") -> PROVOLONE | D4: =IFERROR(__xludf.DUMMYFUNCTION("""COMPUTED_VALUE"""),"") | E4: =IFERROR(__xludf.DUMMYFUNCTION("""COMPUTED_VALUE"""),10.0) -> 10 | F4: =IFERROR(__xludf.DUMMYFUNCTION("""COMPUTED_VALUE"""),"")
A5: =IFERROR(__xludf.DUMMYFUNCTION("""COMPUTED_VALUE"""),"BC-004") -> BC-004 | B5: =IFERROR(__xludf.DUMMYFUNCTION("""COMPUTED_VALUE"""),"entrants") -> entrants | C5: =IFERROR(__xludf.DUMMYFUNCTION("""COMPUTED_VALUE"""),"POLPETTINES D’ALBERGÍNIA") -> POLPETTINES D’ALBERGÍNIA | D5: =IFERROR(__xludf.DUMMYFUNCTION("""COMPUTED_VALUE"""),"6 unitats (cada unitat addicional +1,75 €)") -> 6 unitats (cada unitat addicional +1,75 €) | E5: =IFERROR(__xludf.DUMMYFUNCTION("""COMPUTED_VALUE"""),9.0) -> 9 | F5: =IFERROR(__xludf.DUMMYFUNCTION("""COMPUTED_VALUE"""),"")
A6: =IFERROR(__xludf.DUMMYFUNCTION("""COMPUTED_VALUE"""),"BC-005") -> BC-005 | B6: =IFERROR(__xludf.DUMMYFUNCTION("""COMPUTED_VALUE"""),"entrants") -> entrants | C6: =IFERROR(__xludf.DUMMYFUNCTION("""COMPUTED_VALUE"""),"VITELLO TONNATO") -> VITELLO TONNATO | D6: =IFERROR(__xludf.DUMMYFUNCTION("""COMPUTED_VALUE"""),"Utilitzem carn de vedell / amb salsa de tonyina") -> Utilitzem carn de vedell / amb salsa de tonyina | E6: =IFERROR(__xludf.DUMMYFUNCTION("""COMPUTED_VALUE"""),16.5) -> 16.5 | F6: =IFERROR(__xludf.DUMMYFUNCTION("""COMPUTED_VALUE"""),"")
A7: =IFERROR(__xludf.DUMMYFUNCTION("""COMPUTED_VALUE"""),"BC-006") -> BC-006 | B7: =IFERROR(__xludf.DUMMYFUNCTION("""COMPUTED_VALUE"""),"entrants") -> entrants | C7: =IFERROR(__xludf.DUMMYFUNCTION("""COMPUTED_VALUE"""),"BURRATA") -> BURRATA | D7: =IFERROR(__xludf.DUMMYFUNCTION("""COMPUTED_VALUE"""),"Amb salsa pesto o tòfona / tomàquet sec casolà / ruca / pa") -> Amb salsa pesto o tòfona / tomàquet sec casolà / ruca / pa | E7: =IFERROR(__xludf.DUMMYFUNCTION("""COMPUTED_VALUE"""),15.5) -> 15.5 | F7: =IFERROR(__xludf.DUMMYFUNCTION("""COMPUTED_VALUE"""),"")
A8: =IFERROR(__xludf.DUMMYFUNCTION("""COMPUTED_VALUE"""),"BC-007") -> BC-007 | B8: =IFERROR(__xludf.DUMMYFUNCTION("""COMPUTED_VALUE"""),"entrants") -> entrants | C8: =IFERROR(__xludf.DUMMYFUNCTION("""COMPUTED_VALUE"""),"CARPACCIO DE CARBASSÓ") -> CARPACCIO DE CARBASSÓ | D8: =IFERROR(__xludf.DUMMYFUNCTION("""COMPUTED_VALUE"""),"Amb tomàquets secs, stracciatella i pinyons") -> Amb tomàquets secs, stracciatella i pinyons | E8: =IFERROR(__xludf.DUMMYFUNCTION("""COMPUTED_VALUE"""),15.5) -> 15.5 | F8: =IFERROR(__xludf.DUMMYFUNCTION("""COMPUTED_VALUE"""),"")
A9: =IFERROR(__xludf.DUMMYFUNCTION("""COMPUTED_VALUE"""),"BC-008") -> BC-008 | B9: =IFERROR(__xludf.DUMMYFUNCTION("""COMPUTED_VALUE"""),"amanides") -> amanides | C9: =IFERROR(__xludf.DUMMYFUNCTION("""COMPUTED_VALUE"""),"BELLA CIAO") -> BELLA CIAO | D9: =IFERROR(__xludf.DUMMYFUNCTION("""COMPUTED_VALUE"""),"Albergínia / tomàquet / filadèlfia / julivert / menta / salsa de xili dolça / sèsamo") -> Albergínia / tomàquet / filadèlfia / julivert / menta / salsa de xili dolça / sèsamo | E9: =IFERROR(__xludf.DUMMYFUNCTION("""COMPUTED_VALUE"""),16.0) -> 16 | F9: =IFERROR(__xludf.DUMMYFUNCTION("""COMPUTED_VALUE"""),"")
A10: =IFERROR(__xludf.DUMMYFUNCTION("""COMPUTED_VALUE"""),"BC-009") -> BC-009 | B10: =IFERROR(__xludf.DUMMYFUNCTION("""COMPUTED_VALUE"""),"amanides") -> amanides | C10: =IFERROR(__xludf.DUMMYFUNCTION("""COMPUTED_VALUE"""),"BUFALATA") -> BUFALATA | D10: =IFERROR(__xludf.DUMMYFUNCTION("""COMPUTED_VALUE"""),"Mesclum / burrata / bresaola / nous / olives") -> Mesclum / burrata / bresaola / nous / olives | E10: =IFERROR(__xludf.DUMMYFUNCTION("""COMPUTED_VALUE"""),16.0) -> 16 | F10: =IFERROR(__xludf.DUMMYFUNCTION("""COMPUTED_VALUE"""),"")
A11: =IFERROR(__xludf.DUMMYFUNCTION("""COMPUTED_VALUE"""),"BC-010") -> BC-010 | B11: =IFERROR(__xludf.DUMMYFUNCTION("""COMPUTED_VALUE"""),"amanides") -> amanides | C11: =IFERROR(__xludf.DUMMYFUNCTION("""COMPUTED_VALUE"""),"CÈSAR") -> CÈSAR | D11: =IFERROR(__xludf.DUMMYFUNCTION("""COMPUTED_VALUE"""),"Enciam / pollastre / crostons / cherry / parmesà / salsa cèsar") -> Enciam / pollastre / crostons / cherry / parmesà / salsa cèsar | E11: =IFERROR(__xludf.DUMMYFUNCTION("""COMPUTED_VALUE"""),16.0) -> 16 | F11: =IFERROR(__xludf.DUMMYFUNCTION("""COMPUTED_VALUE"""),"")
A12: =IFERROR(__xludf.DUMMYFUNCTION("""COMPUTED_VALUE"""),"BC-011") -> BC-011 | B12: =IFERROR(__xludf.DUMMYFUNCTION("""COMPUTED_VALUE"""),"amanides") -> amanides | C12: =IFERROR(__xludf.DUMMYFUNCTION("""COMPUTED_VALUE"""),"CABRA") -> CABRA | D12: =IFERROR(__xludf.DUMMYFUNCTION("""COMPUTED_VALUE"""),"Mesclum / cherry / escalivada / albergínia, pebre, ceba / nous / cabra / balsàmic") -> Mesclum / cherry / escalivada / albergínia, pebre, ceba / nous / cabra / balsàmic | E12: =IFERROR(__xludf.DUMMYFUNCTION("""COMPUTED_VALUE"""),16.0) -> 16 | F12: =IFERROR(__xludf.DUMMYFUNCTION("""COMPUTED_VALUE"""),"")
A13: =IFERROR(__xludf.DUMMYFUNCTION("""COMPUTED_VALUE"""),"BC-012") -> BC-012 | B13: =IFERROR(__xludf.DUMMYFUNCTION("""COMPUTED_VALUE"""),"amanides") -> amanides | C13: =IFERROR(__xludf.DUMMYFUNCTION("""COMPUTED_VALUE"""),"LUNA CAPRESE") -> LUNA CAPRESE | D13: =IFERROR(__xludf.DUMMYFUNCTION("""COMPUTED_VALUE"""),"Tomàquet / mozzarella / salsa pesto / ruca / salsa mòdena") -> Tomàquet / mozzarella / salsa pesto / ruca / salsa mòdena | E13: =IFERROR(__xludf.DUMMYFUNCTION("""COMPUTED_VALUE"""),15.5) -> 15.5 | F13: =IFERROR(__xludf.DUMMYFUNCTION("""COMPUTED_VALUE"""),"")
A14: =IFERROR(__xludf.DUMMYFUNCTION("""COMPUTED_VALUE"""),"BC-013") -> BC-013 | B14: =IFERROR(__xludf.DUMMYFUNCTION("""COMPUTED_VALUE"""),"sopes") -> sopes | C14: =IFERROR(__xludf.DUMMYFUNCTION("""COMPUTED_VALUE"""),"SOPA DE LLENTIES") -> SOPA DE LLENTIES | D14: =IFERROR(__xludf.DUMMYFUNCTION("""COMPUTED_VALUE"""),"") | E14: =IFERROR(__xludf.DUMMYFUNCTION("""COMPUTED_VALUE"""),6.0) -> 6 | F14: =IFERROR(__xludf.DUMMYFUNCTION("""COMPUTED_VALUE"""),"")
A15: =IFERROR(__xludf.DUMMYFUNCTION("""COMPUTED_VALUE"""),"BC-014") -> BC-014 | B15: =IFERROR(__xludf.DUMMYFUNCTION("""COMPUTED_VALUE"""),"sopes") -> sopes | C15: =IFERROR(__xludf.DUMMYFUNCTION("""COMPUTED_VALUE"""),"SOPA DE BROCOLI") -> SOPA DE BROCOLI | D15: =IFERROR(__xludf.DUMMYFUNCTION("""COMPUTED_VALUE"""),"") | E15: =IFERROR(__xludf.DUMMYFUNCTION("""COMPUTED_VALUE"""),6.0) -> 6 | F15: =IFERROR(__xludf.DUMMYFUNCTION("""COMPUTED_VALUE"""),"")
A16: =IFERROR(__xludf.DUMMYFUNCTION("""COMPUTED_VALUE"""),"BC-015") -> BC-015 | B16: =IFERROR(__xludf.DUMMYFUNCTION("""COMPUTED_VALUE"""),"carn") -> carn | C16: =IFERROR(__xludf.DUMMYFUNCTION("""COMPUTED_VALUE"""),"CARPACCIO DE BOU") -> CARPACCIO DE BOU | D16: =IFERROR(__xludf.DUMMYFUNCTION("""COMPUTED_VALUE"""),"") | E16: =IFERROR(__xludf.DUMMYFUNCTION("""COMPUTED_VALUE"""),15.0) -> 15 | F16: =IFERROR(__xludf.DUMMYFUNCTION("""COMPUTED_VALUE"""),"")
A17: =IFERROR(__xludf.DUMMYFUNCTION("""COMPUTED_VALUE"""),"BC-016") -> BC-016 | B17: =IFERROR(__xludf.DUMMYFUNCTION("""COMPUTED_VALUE"""),"carn") -> carn | C17: =IFERROR(__xludf.DUMMYFUNCTION("""COMPUTED_VALUE"""),"ENTRECOT DE BOU") -> ENTRECOT DE BOU | D17: =IFERROR(__xludf.DUMMYFUNCTION("""COMPUTED_VALUE"""),"") | E17: =IFERROR(__xludf.DUMMYFUNCTION("""COMPUTED_VALUE"""),8.5) -> 8.5 | F17: =IFERROR(__xludf.DUMMYFUNCTION("""COMPUTED_VALUE"""),"")
A18: =IFERROR(__xludf.DUMMYFUNCTION("""COMPUTED_VALUE"""),"BC-017") -> BC-017 | B18: =IFERROR(__xludf.DUMMYFUNCTION("""COMPUTED_VALUE"""),"carn") -> carn | C18: =IFERROR(__xludf.DUMMYFUNCTION("""COMPUTED_VALUE"""),"EMBOTITS ITALIANS") -> EMBOTITS ITALIANS | D18: =IFERROR(__xludf.DUMMYFUNCTION("""COMPUTED_VALUE"""),"Bresaola / salami / mortadel·la de tòfona / mortadel·la de pistatxos / la piatta piccante") -> Bresaola / salami / mortadel·la de tòfona / mortadel·la de pistatxos / la piatta piccante | E18: =IFERROR(__xludf.DUMMYFUNCTION("""COMPUTED_VALUE"""),22.5) -> 22.5 | F18: =IFERROR(__xludf.DUMMYFUNCTION("""COMPUTED_VALUE"""),"")
A19: =IFERROR(__xludf.DUMMYFUNCTION("""COMPUTED_VALUE"""),"BC-018") -> BC-018 | B19: =IFERROR(__xludf.DUMMYFUNCTION("""COMPUTED_VALUE"""),"pasta") -> pasta | C19: =IFERROR(__xludf.DUMMYFUNCTION("""COMPUTED_VALUE"""),"BIGOLI ALLA NAPOLITANA") -> BIGOLI ALLA NAPOLITANA | D19: =IFERROR(__xludf.DUMMYFUNCTION("""COMPUTED_VALUE"""),"Pasta amb tomàquets") -> Pasta amb tomàquets | E19: =IFERROR(__xludf.DUMMYFUNCTION("""COMPUTED_VALUE"""),9.5) -> 9.5 | F19: =IFERROR(__xludf.DUMMYFUNCTION("""COMPUTED_VALUE"""),"")
A20: =IFERROR(__xludf.DUMMYFUNCTION("""COMPUTED_VALUE"""),"BC-019") -> BC-019 | B20: =IFERROR(__xludf.DUMMYFUNCTION("""COMPUTED_VALUE"""),"pasta") -> pasta | C20: =IFERROR(__xludf.DUMMYFUNCTION("""COMPUTED_VALUE"""),"TAGLIATELLE TARTUFATA") -> TAGLIATELLE TARTUFATA | D20: =IFERROR(__xludf.DUMMYFUNCTION("""COMPUTED_VALUE"""),"Amb crema de tòfona") -> Amb crema de tòfona | E20: =IFERROR(__xludf.DUMMYFUNCTION("""COMPUTED_VALUE"""),14.0) -> 14 | F20: =IFERROR(__xludf.DUMMYFUNCTION("""COMPUTED_VALUE"""),"")
A21: =IFERROR(__xludf.DUMMYFUNCTION("""COMPUTED_VALUE"""),"BC-020") -> BC-020 | B21: =IFERROR(__xludf.DUMMYFUNCTION("""COMPUTED_VALUE"""),"pasta") -> pasta | C21: =IFERROR(__xludf.DUMMYFUNCTION("""COMPUTED_VALUE"""),"GARGANELLI ALL’ARRABBIATA") -> GARGANELLI ALL’ARRABBIATA | D21: =IFERROR(__xludf.DUMMYFUNCTION("""COMPUTED_VALUE"""),"Salsa picant tradicional casolana") -> Salsa picant tradicional casolana | E21: =IFERROR(__xludf.DUMMYFUNCTION("""COMPUTED_VALUE"""),14.0) -> 14 | F21: =IFERROR(__xludf.DUMMYFUNCTION("""COMPUTED_VALUE"""),"")
A22: =IFERROR(__xludf.DUMMYFUNCTION("""COMPUTED_VALUE"""),"BC-021") -> BC-021 | B22: =IFERROR(__xludf.DUMMYFUNCTION("""COMPUTED_VALUE"""),"pasta") -> pasta | C22: =IFERROR(__xludf.DUMMYFUNCTION("""COMPUTED_VALUE"""),"SPAGHETTI RAGÚ ALLA BOLOGNESE") -> SPAGHETTI RAGÚ ALLA BOLOGNESE | D22: =IFERROR(__xludf.DUMMYFUNCTION("""COMPUTED_VALUE"""),"Salsa casolana de carn d'Andorra") -> Salsa casolana de carn d'Andorra | E22: =IFERROR(__xludf.DUMMYFUNCTION("""COMPUTED_VALUE"""),15.5) -> 15.5 | F22: =IFERROR(__xludf.DUMMYFUNCTION("""COMPUTED_VALUE"""),"")
A23: =IFERROR(__xludf.DUMMYFUNCTION("""COMPUTED_VALUE"""),"BC-022") -> BC-022 | B23: =IFERROR(__xludf.DUMMYFUNCTION("""COMPUTED_VALUE"""),"pasta") -> pasta | C23: =IFERROR(__xludf.DUMMYFUNCTION("""COMPUTED_VALUE"""),"TAGLIATELLE 4 FORMATGES") -> TAGLIATELLE 4 FORMATGES | D23: =IFERROR(__xludf.DUMMYFUNCTION("""COMPUTED_VALUE"""),"Mozzarella / cabra / emmental / gorgonzola") -> Mozzarella / cabra / emmental / gorgonzola | E23: =IFERROR(__xludf.DUMMYFUNCTION("""COMPUTED_VALUE"""),15.5) -> 15.5 | F23: =IFERROR(__xludf.DUMMYFUNCTION("""COMPUTED_VALUE"""),"")
A24: =IFERROR(__xludf.DUMMYFUNCTION("""COMPUTED_VALUE"""),"BC-023") -> BC-023 | B24: =IFERROR(__xludf.DUMMYFUNCTION("""COMPUTED_VALUE"""),"pasta") -> pasta | C24: =IFERROR(__xludf.DUMMYFUNCTION("""COMPUTED_VALUE"""),"LINGUINE D’ALL I ALFÀBREGA AMB PESTO") -> LINGUINE D’ALL I ALFÀBREGA AMB PESTO | D24: =IFERROR(__xludf.DUMMYFUNCTION("""COMPUTED_VALUE"""),"Salsa casolana d’alfàbrega de quilòmetre 0") -> Salsa casolana d’alfàbrega de quilòmetre 0 | E24: =IFERROR(__xludf.DUMMYFUNCTION("""COMPUTED_VALUE"""),15.5) -> 15.5 | F24: =IFERROR(__xludf.DUMMYFUNCTION("""COMPUTED_VALUE"""),"")
A25: =IFERROR(__xludf.DUMMYFUNCTION("""COMPUTED_VALUE"""),"BC-024") -> BC-024 | B25: =IFERROR(__xludf.DUMMYFUNCTION("""COMPUTED_VALUE"""),"pasta") -> pasta | C25: =IFERROR(__xludf.DUMMYFUNCTION("""COMPUTED_VALUE"""),"BIGOLI ALLA CARBONARA") -> BIGOLI ALLA CARBONARA | D25: =IFERROR(__xludf.DUMMYFUNCTION("""COMPUTED_VALUE"""),"Recepta tradicional amb ous i guanciale") -> Recepta tradicional amb ous i guanciale | E25: =IFERROR(__xludf.DUMMYFUNCTION("""COMPUTED_VALUE"""),17.0) -> 17 | F25: =IFERROR(__xludf.DUMMYFUNCTION("""COMPUTED_VALUE"""),"")
A26: =IFERROR(__xludf.DUMMYFUNCTION("""COMPUTED_VALUE"""),"BC-025") -> BC-025 | B26: =IFERROR(__xludf.DUMMYFUNCTION("""COMPUTED_VALUE"""),"pasta") -> pasta | C26: =IFERROR(__xludf.DUMMYFUNCTION("""COMPUTED_VALUE"""),"SPAGHETTI NERI FRUTTI DI MARE") -> SPAGHETTI NERI FRUTTI DI MARE | D26: =IFERROR(__xludf.DUMMYFUNCTION("""COMPUTED_VALUE"""),"Salsa de tomàquets cherry / gambes / cloïsses / musclos") -> Salsa de tomàquets cherry / gambes / cloïsses / musclos | E26: =IFERROR(__xludf.DUMMYFUNCTION("""COMPUTED_VALUE"""),22.0) -> 22 | F26: =IFERROR(__xludf.DUMMYFUNCTION("""COMPUTED_VALUE"""),"")
A27: =IFERROR(__xludf.DUMMYFUNCTION("""COMPUTED_VALUE"""),"BC-026") -> BC-026 | B27: =IFERROR(__xludf.DUMMYFUNCTION("""COMPUTED_VALUE"""),"pasta_farcida") -> pasta_farcida | C27: =IFERROR(__xludf.DUMMYFUNCTION("""COMPUTED_VALUE"""),"RAVIOLIS DE BOLETS") -> RAVIOLIS DE BOLETS | D27: =IFERROR(__xludf.DUMMYFUNCTION("""COMPUTED_VALUE"""),"Servit amb salsa casolana de pesto") -> Servit amb salsa casolana de pesto | E27: =IFERROR(__xludf.DUMMYFUNCTION("""COMPUTED_VALUE"""),17.5) -> 17.5 | F27: =IFERROR(__xludf.DUMMYFUNCTION("""COMPUTED_VALUE"""),"")
A28: =IFERROR(__xludf.DUMMYFUNCTION("""COMPUTED_VALUE"""),"BC-027") -> BC-027 | B28: =IFERROR(__xludf.DUMMYFUNCTION("""COMPUTED_VALUE"""),"pasta_farcida") -> pasta_farcida | C28: =IFERROR(__xludf.DUMMYFUNCTION("""COMPUTED_VALUE"""),"FIOCCHI AMB PERA I RICOTTA") -> FIOCCHI AMB PERA I RICOTTA | D28: =IFERROR(__xludf.DUMMYFUNCTION("""COMPUTED_VALUE"""),"Servit amb crema de carbassa casolana") -> Servit amb crema de carbassa casolana | E28: =IFERROR(__xludf.DUMMYFUNCTION("""COMPUTED_VALUE"""),17.0) -> 17 | F28: =IFERROR(__xludf.DUMMYFUNCTION("""COMPUTED_VALUE"""),"")
A29: =IFERROR(__xludf.DUMMYFUNCTION("""COMPUTED_VALUE"""),"BC-028") -> BC-028 | B29: =IFERROR(__xludf.DUMMYFUNCTION("""COMPUTED_VALUE"""),"pasta_farcida") -> pasta_farcida | C29: =IFERROR(__xludf.DUMMYFUNCTION("""COMPUTED_VALUE"""),"CANELONS DE CARN") -> CANELONS DE CARN | D29: =IFERROR(__xludf.DUMMYFUNCTION("""COMPUTED_VALUE"""),"Canelons fets per nosaltres servits amb salsa boloñesa casolana") -> Canelons fets per nosaltres servits amb salsa boloñesa casolana | E29: =IFERROR(__xludf.DUMMYFUNCTION("""COMPUTED_VALUE"""),13.5) -> 13.5 | F29: =IFERROR(__xludf.DUMMYFUNCTION("""COMPUTED_VALUE"""),"")
A30: =IFERROR(__xludf.DUMMYFUNCTION("""COMPUTED_VALUE"""),"BC-029") -> BC-029 | B30: =IFERROR(__xludf.DUMMYFUNCTION("""COMPUTED_VALUE"""),"pasta_farcida") -> pasta_farcida | C30: =IFERROR(__xludf.DUMMYFUNCTION("""COMPUTED_VALUE"""),"NYOQUIS") -> NYOQUIS | D30: =IFERROR(__xludf.DUMMYFUNCTION("""COMPUTED_VALUE"""),"Crema de tomàquet fresc i stracciatella") -> Crema de tomàquet fresc i stracciatella | E30: =IFERROR(__xludf.DUMMYFUNCTION("""COMPUTED_VALUE"""),16.0) -> 16 | F30: =IFERROR(__xludf.DUMMYFUNCTION("""COMPUTED_VALUE"""),"")
A31: =IFERROR(__xludf.DUMMYFUNCTION("""COMPUTED_VALUE"""),"BC-030") -> BC-030 | B31: =IFERROR(__xludf.DUMMYFUNCTION("""COMPUTED_VALUE"""),"pasta_farcida") -> pasta_farcida | C31: =IFERROR(__xludf.DUMMYFUNCTION("""COMPUTED_VALUE"""),"LASANYA BOLONYESA") -> LASANYA BOLONYESA | D31: =IFERROR(__xludf.DUMMYFUNCTION("""COMPUTED_VALUE"""),"Feta per nosaltres / salsa bolonyesa casolana") -> Feta per nosaltres / salsa bolonyesa casolana | E31: =IFERROR(__xludf.DUMMYFUNCTION("""COMPUTED_VALUE"""),15.5) -> 15.5 | F31: =IFERROR(__xludf.DUMMYFUNCTION("""COMPUTED_VALUE"""),"")
A32: =IFERROR(__xludf.DUMMYFUNCTION("""COMPUTED_VALUE"""),"BC-031") -> BC-031 | B32: =IFERROR(__xludf.DUMMYFUNCTION("""COMPUTED_VALUE"""),"pasta_farcida") -> pasta_farcida | C32: =IFERROR(__xludf.DUMMYFUNCTION("""COMPUTED_VALUE"""),"RISOTTO DE BOLETS") -> RISOTTO DE BOLETS | D32: =IFERROR(__xludf.DUMMYFUNCTION("""COMPUTED_VALUE"""),"Amb crema de tòfona") -> Amb crema de tòfona | E32: =IFERROR(__xludf.DUMMYFUNCTION("""COMPUTED_VALUE"""),19.0) -> 19 | F32: =IFERROR(__xludf.DUMMYFUNCTION("""COMPUTED_VALUE"""),"")
A33: =IFERROR(__xludf.DUMMYFUNCTION("""COMPUTED_VALUE"""),"BC-032") -> BC-032 | B33: =IFERROR(__xludf.DUMMYFUNCTION("""COMPUTED_VALUE"""),"pizzes") -> pizzes | C33: =IFERROR(__xludf.DUMMYFUNCTION("""COMPUTED_VALUE"""),"MARGARITA") -> MARGARITA | D33: =IFERROR(__xludf.DUMMYFUNCTION("""COMPUTED_VALUE"""),"Tomàquet / mozzarella") -> Tomàquet / mozzarella | E33: =IFERROR(__xludf.DUMMYFUNCTION("""COMPUTED_VALUE"""),12.0) -> 12 | F33: =IFERROR(__xludf.DUMMYFUNCTION("""COMPUTED_VALUE"""),"")
A34: =IFERROR(__xludf.DUMMYFUNCTION("""COMPUTED_VALUE"""),"BC-033") -> BC-033 | B34: =IFERROR(__xludf.DUMMYFUNCTION("""COMPUTED_VALUE"""),"pizzes") -> pizzes | C34: =IFERROR(__xludf.DUMMYFUNCTION("""COMPUTED_VALUE"""),"PROSCIUTO") -> PROSCIUTO | D34: =IFERROR(__xludf.DUMMYFUNCTION("""COMPUTED_VALUE"""),"Tomàquet / mozzarella / pernil dolç") -> Tomàquet / mozzarella / pernil dolç | E34: =IFERROR(__xludf.DUMMYFUNCTION("""COMPUTED_VALUE"""),14.5) -> 14.5 | F34: =IFERROR(__xludf.DUMMYFUNCTION("""COMPUTED_VALUE"""),"")
A35: =IFERROR(__xludf.DUMMYFUNCTION("""COMPUTED_VALUE"""),"BC-034") -> BC-034 | B35: =IFERROR(__xludf.DUMMYFUNCTION("""COMPUTED_VALUE"""),"pizzes") -> pizzes | C35: =IFERROR(__xludf.DUMMYFUNCTION("""COMPUTED_VALUE"""),"REGINA") -> REGINA | D35: =IFERROR(__xludf.DUMMYFUNCTION("""COMPUTED_VALUE"""),"Tomàquet / mozzarella / pernil dolç / xampinyons") -> Tomàquet / mozzarella / pernil dolç / xampinyons | E35: =IFERROR(__xludf.DUMMYFUNCTION("""COMPUTED_VALUE"""),15.0) -> 15 | F35: =IFERROR(__xludf.DUMMYFUNCTION("""COMPUTED_VALUE"""),"")
A36: =IFERROR(__xludf.DUMMYFUNCTION("""COMPUTED_VALUE"""),"BC-035") -> BC-035 | B36: =IFERROR(__xludf.DUMMYFUNCTION("""COMPUTED_VALUE"""),"pizzes") -> pizzes | C36: =IFERROR(__xludf.DUMMYFUNCTION("""COMPUTED_VALUE"""),"CALZONE") -> CALZONE | D36: =IFERROR(__xludf.DUMMYFUNCTION("""COMPUTED_VALUE"""),"Tomàquet / mozzarella / pernil dolç / ou") -> Tomàquet / mozzarella / pernil dolç / ou | E36: =IFERROR(__xludf.DUMMYFUNCTION("""COMPUTED_VALUE"""),17.0) -> 17 | F36: =IFERROR(__xludf.DUMMYFUNCTION("""COMPUTED_VALUE"""),"")
A37: =IFERROR(__xludf.DUMMYFUNCTION("""COMPUTED_VALUE"""),"BC-036") -> BC-036 | B37: =IFERROR(__xludf.DUMMYFUNCTION("""COMPUTED_VALUE"""),"pizzes") -> pizzes | C37: =IFERROR(__xludf.DUMMYFUNCTION("""COMPUTED_VALUE"""),"PEPPERONI") -> PEPPERONI | D37: =IFERROR(__xludf.DUMMYFUNCTION("""COMPUTED_VALUE"""),"Tomàquet / mozzarella / pepperoni / bitxo verd") -> Tomàquet / mozzarella / pepperoni / bitxo verd | E37: =IFERROR(__xludf.DUMMYFUNCTION("""COMPUTED_VALUE"""),15.5) -> 15.5 | F37: =IFERROR(__xludf.DUMMYFUNCTION("""COMPUTED_VALUE"""),"")
A38: =IFERROR(__xludf.DUMMYFUNCTION("""COMPUTED_VALUE"""),"BC-037") -> BC-037 | B38: =IFERROR(__xludf.DUMMYFUNCTION("""COMPUTED_VALUE"""),"pizzes") -> pizzes | C38: =IFERROR(__xludf.DUMMYFUNCTION("""COMPUTED_VALUE"""),"CAPRESE") -> CAPRESE | D38: =IFERROR(__xludf.DUMMYFUNCTION("""COMPUTED_VALUE"""),"Tomàquet / mozzarella fresca / tomàquet sec casolà / alfàbrega") -> Tomàquet / mozzarella fresca / tomàquet sec casolà / alfàbrega | E38: =IFERROR(__xludf.DUMMYFUNCTION("""COMPUTED_VALUE"""),15.5) -> 15.5 | F38: =IFERROR(__xludf.DUMMYFUNCTION("""COMPUTED_VALUE"""),"")
A39: =IFERROR(__xludf.DUMMYFUNCTION("""COMPUTED_VALUE"""),"BC-038") -> BC-038 | B39: =IFERROR(__xludf.DUMMYFUNCTION("""COMPUTED_VALUE"""),"pizzes") -> pizzes | C39: =IFERROR(__xludf.DUMMYFUNCTION("""COMPUTED_VALUE"""),"GAMBES") -> GAMBES | D39: =IFERROR(__xludf.DUMMYFUNCTION("""COMPUTED_VALUE"""),"Tomàquet / mozzarella / gambes / all-julivert / oli") -> Tomàquet / mozzarella / gambes / all-julivert / oli | E39: =IFERROR(__xludf.DUMMYFUNCTION("""COMPUTED_VALUE"""),18.0) -> 18 | F39: =IFERROR(__xludf.DUMMYFUNCTION("""COMPUTED_VALUE"""),"")
A40: =IFERROR(__xludf.DUMMYFUNCTION("""COMPUTED_VALUE"""),"BC-039") -> BC-039 | B40: =IFERROR(__xludf.DUMMYFUNCTION("""COMPUTED_VALUE"""),"pizzes") -> pizzes | C40: =IFERROR(__xludf.DUMMYFUNCTION("""COMPUTED_VALUE"""),"IBÉRICA") -> IBÉRICA | D40: =IFERROR(__xludf.DUMMYFUNCTION("""COMPUTED_VALUE"""),"Tomàquet / mozzarella / pernil ibèric / parmesà / ruca") -> Tomàquet / mozzarella / pernil ibèric / parmesà / ruca | E40: =IFERROR(__xludf.DUMMYFUNCTION("""COMPUTED_VALUE"""),18.5) -> 18.5 | F40: =IFERROR(__xludf.DUMMYFUNCTION("""COMPUTED_VALUE"""),"")
...

Sheet WEB
A1: ID | B1: Categoría | C1: Producto | D1: Ingredientes / detalle | E1: Precio (€) | F1: Imagen URL
A2: =IFERROR(__xludf.DUMMYFUNCTION("IFERROR(FILTER(HSTACK(MAESTRA!A2:A200,MAESTRA!C2:C200,IF(CONTROL!$B$4=""CAT"",MAESTRA!D2:D200,IF(CONTROL!$B$4=""ES"",MAESTRA!F2:F200,IF(CONTROL!$B$4=""FR"",MAESTRA!H2:H200,MAESTRA!J2:J200))),IF(CONTROL!$B$4=""CAT"",MAESTRA!E2:E200,IF(CONTROL!$B$4=""ES"",M"&"AESTRA!G2:G200,IF(CONTROL!$B$4=""FR"",MAESTRA!I2:I200,MAESTRA!K2:K200))),MAESTRA!L2:L200,MAESTRA!R2:R200),MAESTRA!A2:A200<>"""",MAESTRA!P2:P200=TRUE),"""")"),"BC-001") -> BC-001 | B2: =IFERROR(__xludf.DUMMYFUNCTION("""COMPUTED_VALUE"""),"entrants") -> entrants | C2: =IFERROR(__xludf.DUMMYFUNCTION("""COMPUTED_VALUE"""),"PA DE PIZZA") -> PA DE PIZZA | D2: =IFERROR(__xludf.DUMMYFUNCTION("""COMPUTED_VALUE"""),"Massa normal / integral") -> Massa normal / integral | E2: =IFERROR(__xludf.DUMMYFUNCTION("""COMPUTED_VALUE"""),5.0) -> 5 | F2: =IFERROR(__xludf.DUMMYFUNCTION("""COMPUTED_VALUE"""),"")
